import asyncio

import aiohttp
import pytest

import ya_activity
import ya_market
import ya_payment

from yapapi.rest.common import SuppressedExceptions, is_intermittent_error, repeat_on_error


@pytest.mark.parametrize(
    "max_tries, exceptions, calls_expected, expected_error",
    [
        (1, [], 1, None),
        (1, [asyncio.TimeoutError()], 1, asyncio.TimeoutError),
        (1, [ya_activity.ApiException(408)], 1, ya_activity.ApiException),
        (1, [ya_activity.ApiException(500)], 1, ya_activity.ApiException),
        (1, [ValueError()], 1, ValueError),
        #
        (2, [], 1, None),
        (2, [asyncio.TimeoutError()], 2, None),
        (2, [ya_activity.ApiException(408)], 2, None),
        (2, [ya_market.ApiException(408)], 2, None),
        (2, [ya_payment.ApiException(408)], 2, None),
        (2, [ya_activity.ApiException(500)], 1, ya_activity.ApiException),
        (2, [aiohttp.ServerDisconnectedError()], 2, None),
        (2, [aiohttp.ClientOSError(32, "Broken pipe")], 2, None),
        (2, [aiohttp.ClientOSError(1132, "UnBroken pipe")], 1, aiohttp.ClientOSError),
        (2, [ValueError()], 1, ValueError),
        (2, [asyncio.TimeoutError()] * 2, 2, asyncio.TimeoutError),
        #
        (3, [], 1, None),
        (3, [asyncio.TimeoutError()], 2, None),
        (3, [ya_activity.ApiException(408)], 2, None),
        (3, [asyncio.TimeoutError()] * 2, 3, None),
        (3, [asyncio.TimeoutError()] * 3, 3, asyncio.TimeoutError),
        (3, [ya_activity.ApiException(500)], 1, ya_activity.ApiException),
        (3, [asyncio.TimeoutError(), ValueError()], 2, ValueError),
    ],
)
@pytest.mark.asyncio
async def test_repeat_on_error(max_tries, exceptions, calls_expected, expected_error):
    calls_made = 0

    @repeat_on_error(max_tries=max_tries, interval=0.0)
    async def request():
        nonlocal calls_made, exceptions
        calls_made += 1
        if exceptions:
            e = exceptions[0]
            exceptions = exceptions[1:]
            raise e
        return True

    try:
        await request()
    except Exception as e:
        assert expected_error is not None, f"Unexpected exception: {e}"
        assert isinstance(e, expected_error), f"Expected an {expected_error}, got {e}"
    assert (
        calls_made == calls_expected
    ), f"{calls_made} attempts were made, expected {calls_expected}"


@pytest.mark.asyncio
async def test_suppressed_exceptions():
    async with SuppressedExceptions(is_intermittent_error) as se:
        pass
    assert se.exception is None

    async with SuppressedExceptions(is_intermittent_error) as se:
        raise asyncio.TimeoutError()
    assert isinstance(se.exception, asyncio.TimeoutError)

    async with SuppressedExceptions(is_intermittent_error) as se:
        raise aiohttp.ClientOSError(32, "Broken pipe")
    assert isinstance(se.exception, aiohttp.ClientOSError)

    async with SuppressedExceptions(is_intermittent_error) as se:
        raise aiohttp.ServerDisconnectedError()
    assert isinstance(se.exception, aiohttp.ServerDisconnectedError)

    with pytest.raises(AssertionError):
        async with SuppressedExceptions(is_intermittent_error):
            raise AssertionError()


@pytest.mark.asyncio
async def test_suppressed_exceptions_with_return():
    async def success():
        return "success"

    async def failure():
        raise asyncio.TimeoutError()

    async def func(request):
        async with SuppressedExceptions(is_intermittent_error):
            return await request
        return "failure"  # noqa

    assert await func(success()) == "success"
    assert await func(failure()) == "failure"
